<?xml version="1.0" encoding="utf-8"?>
<!-- This URDF was automatically created by SolidWorks to URDF Exporter! Originally created by Stephen Brawner (brawner@gmail.com) 
     Commit Version: 1.6.0-1-g15f4949  Build Version: 1.6.7594.29634
     For more information, please see http://wiki.ros.org/sw_urdf_exporter -->
<robot name="streeing_arm">
  <link name="arm_base_link">
    <inertial>
      <origin xyz="0.000199683039820826 0.005145144147916 0.012410896975763" rpy="0 0 0" />
      <mass value="0.0380299146996912" />
      <inertia
        ixx="6.59286998207165E-06"
        ixy="-1.5207196189166E-07"
        ixz="-6.1163552263237E-11"
        iyy="7.36864724408771E-06"
        iyz="1.45081779342908E-07"
        izz="1.12027270721149E-05" />
    </inertial>
    <visual>
      <origin xyz="0 0 0" rpy="0 0 0" />
      <geometry>
        <mesh filename="package://streeing_arm/meshes/base_link.STL" />
      </geometry>
      <material name="">
        <color rgba="0.741176470588235 0.901960784313726 0.956862745098039 1" />
      </material>
    </visual>
    <collision>
      <origin xyz="0 0 0" rpy="0 0 0" />
      <geometry>
        <mesh filename="package://streeing_arm/meshes/base_link.STL" />
      </geometry>
    </collision>
  </link>

  <link name="link_1">
    <inertial>
      <origin xyz="0.0304931121507161 4.94829871522384E-16 0.0525"  rpy="0 0 0" />
      <mass value="0.0182961255655795" />
      <inertia
        ixx="7.56857037469896E-06"
        ixy="-1.41852472239301E-19"
        ixz="-7.39088633164791E-21"
        iyy="1.62397575138123E-05"
        iyz="4.76456032830354E-22"
        izz="1.05132687532747E-05" />
    </inertial>
    <visual>
      <origin xyz="0 0 0" rpy="0 0 0" />
      <geometry>
        <mesh filename="package://streeing_arm/meshes/link_1.STL" />
      </geometry>
      <material name="">
        <color rgba="0.741176470588235 0.901960784313726 0.956862745098039 1" />
      </material>
    </visual>
    <collision>
      <origin xyz="0 0 0" rpy="0 0 0" />
      <geometry>
        <mesh filename="package://streeing_arm/meshes/link_1.STL" />
      </geometry>
    </collision>
  </link>

  <joint name="joint_1" type="revolute">
    <origin xyz="0.01 -0.020402 0.0135" rpy="0.0 0 1.5708" />
    <parent link="arm_base_link" />
    <child link="link_1" />
    <axis xyz="1 0 0" />
    <limit lower="0" upper="1.57" effort="100" velocity="3" />
  </joint>

  <link name="link_2">
    <inertial>
      <origin xyz="0.0257576432953458 0.00137715430708122 0.0206842707646627" rpy="0 0 0" />
      <mass value="0.0488195362560629" />
      <inertia
        ixx="1.15881140577187E-05"
        ixy="-1.43514518682294E-07"
        ixz="1.53551903987917E-07"
        iyy="1.97481412401206E-05"
        iyz="5.13246778264873E-08"
        izz="1.2125688470375E-05" />
    </inertial>
    <visual>
      <origin xyz="0 0 0" rpy="0 0 0" />
      <geometry>
        <mesh filename="package://streeing_arm/meshes/link_2.STL" />
      </geometry>
      <material name="">
        <color rgba="0.741176470588235 0.901960784313726 0.956862745098039 1" />
      </material>
    </visual>
    <collision>
      <origin xyz="0 0 0" rpy="0 0 0" />
      <geometry>
        <mesh filename="package://streeing_arm/meshes/link_2.STL" />
      </geometry>
    </collision>
  </link>

  <joint name="joint_2" type="revolute">
    <origin xyz="0 0 0.105" rpy="0 0 0" />
    <parent link="link_1" />
    <child link="link_2" />
    <axis xyz="1 0 0" />
    <limit lower="-1.57" upper="1.57" effort="100" velocity="3" />
  </joint>

  <link name="link_3">
    <inertial>
      <origin xyz="0.022461275278841 -0.00485434547928628 0.0330325603677447" rpy="0 0 0" />
      <mass value="0.0777215526484572" />
      <inertia
        ixx="1.297581319738E-05"
        ixy="-1.22287232933419E-07"
        ixz="1.60399323784462E-07"
        iyy="1.8770071220371E-05"
        iyz="-2.61891299098186E-07"
        izz="1.69444016979507E-05" />
    </inertial>
    <visual>
      <origin xyz="0 0 0" rpy="0 0 0" />
      <geometry>
        <mesh filename="package://streeing_arm/meshes/link_3.STL" />
      </geometry>
      <material name="">
        <color rgba="0.741176470588235 0.901960784313726 0.956862745098039 1" />
      </material>
    </visual>
    <collision>
      <origin xyz="0 0 0" rpy="0 0 0" />
      <geometry>
        <mesh filename="package://streeing_arm/meshes/link_3.STL" />
      </geometry>
    </collision>
  </link>

  <joint name="joint_3" type="revolute">
    <origin xyz="-0.0015 0 0.097505" rpy="0.12 0 0" />
    <parent link="link_2" />
    <child link="link_3" />
    <axis xyz="1 0 0" />
    <limit lower="-1.57" upper="1.57" effort="100" velocity="3" />
  </joint>

  <link name="link_4">
    <inertial>
      <origin xyz="-0.00564731558518881 0.00150000000000139 0.00640801185701134" rpy="0 0 0" />
      <mass value="0.00197604548440536" />
      <inertia
        ixx="1.95368168459778E-07"
        ixy="1.38081190332098E-22"
        ixz="1.51745831304819E-07"
        iyy="3.99845023290352E-07"
        iyz="-6.93648647047897E-21"
        izz="2.07440923057183E-07" />
    </inertial>
    <visual>
      <origin xyz="0 0 0" rpy="0 0 0" />
      <geometry>
        <mesh filename="package://streeing_arm/meshes/link_4.STL" />
      </geometry>
      <material name="">
        <color rgba="0.741176470588235 0.901960784313726 0.956862745098039 1" />
      </material>
    </visual>
    <collision>
      <origin xyz="0 0 0"  rpy="0 0 0" />
      <geometry>
        <mesh  filename="package://streeing_arm/meshes/link_4.STL" />
      </geometry>
    </collision>
  </link>

  <joint  name="joint_4"  type="revolute">
    <origin  xyz="0.034 0.013958 0.052568"  rpy="0.13973 0 -3.1416" />
    <parent  link="link_3" />
    <child  link="link_4" />
    <axis  xyz="0 -1 0" />
    <limit  lower="-0.8"  upper="0.8"  effort="100"  velocity="3" />
  </joint>

  <link name="link_8">
    <inertial>
      <origin  xyz="-0.00614995179393875 0.0103163534952073 0.0192779652005062"  rpy="0 0 0" />
      <mass  value="0.0110869952460788" />
      <inertia
        ixx="2.26639796636765E-06"
        ixy="2.86299548209749E-14"
        ixz="-3.12170251804134E-07"
        iyy="2.52356232166153E-06"
        iyz="2.26204071684424E-13"
        izz="7.09382869443721E-07" />
    </inertial>
    <visual>
      <origin  xyz="0 0 0"  rpy="0 0 0" />
      <geometry>
        <mesh  filename="package://streeing_arm/meshes/link_8.STL" />
      </geometry>
      <material  name="">
        <color  rgba="0.741176470588235 0.901960784313726 0.956862745098039 1" />
      </material>
    </visual>
    <collision>
      <origin  xyz="0 0 0"  rpy="0 0 0" />
      <geometry>
        <mesh  filename="package://streeing_arm/meshes/link_8.STL" />
      </geometry>
    </collision>
  </link>

  <joint  name="joint_8"  type="revolute">
    <origin  xyz="-0.024471 -0.004 0.025023"  rpy="0 0 0" />
    <parent  link="link_4" />
    <child  link="link_8" />
    <axis  xyz="0 -1 0" />
    <limit  lower="-0.8"  upper="0.8"  effort="100"  velocity="3" />
  </joint>

  <link  name="link_5">
    <inertial>
      <origin  xyz="0.00369362330435792 0.00223507058766409 0.0043613275739503"  rpy="0 0 0" />
      <mass  value="0.0029710856680058" />
      <inertia
        ixx="2.05767246894327E-07"
        ixy="-1.73944789062283E-21"
        ixz="-1.40876829989061E-07"
        iyy="4.07485385419228E-07"
        iyz="-1.58138773852585E-21"
        izz="2.13065038138551E-07" />
    </inertial>
    <visual>
      <origin  xyz="0 0 0"  rpy="0 0 0" />
      <geometry>
        <mesh  filename="package://streeing_arm/meshes/link_5.STL" />
      </geometry>
      <material  name="">
        <color  rgba="0.741176470588235 0.901960784313726 0.956862745098039 1" />
      </material>
    </visual>
    <collision>
      <origin  xyz="0 0 0" rpy="0 0 0" />
      <geometry>
        <mesh  filename="package://streeing_arm/meshes/link_5.STL" />
      </geometry>
    </collision>
  </link>

  <joint  name="joint_5" type="revolute">
    <origin  xyz="0.009 0.013958 0.052568"  rpy="0.13973 0 -3.1416" />
    <parent link="link_3" />
    <child  link="link_5" />
    <axis  xyz="0 1 0" />
    <limit  lower="-0.8"  upper="0.8"  effort="100"  velocity="3" />
  </joint>

  <link  name="link_9">
    <inertial>
      <origin  xyz="0.00634496611832598 0.0110972731697096 0.020560294407977"  rpy="0 0 0" />
      <mass  value="0.0102295319024209" />
      <inertia
        ixx="2.2117714850267E-06"
        ixy="-1.90044159812695E-15"
        ixz="2.98211660889234E-07"
        iyy="2.41260879364446E-06"
        iyz="2.25907313831134E-13"
        izz="6.52484215993186E-07" />
    </inertial>
    <visual>
      <origin  xyz="0 0 0"  rpy="0 0 0" />
      <geometry>
        <mesh  filename="package://streeing_arm/meshes/link_9.STL" />
      </geometry>
      <material  name="">
        <color  rgba="0.741176470588235 0.901960784313726 0.956862745098039 1" />
      </material>
    </visual>
    <collision>
      <origin  xyz="0 0 0"  rpy="0 0 0" />
      <geometry>
        <mesh  filename="package://streeing_arm/meshes/link_9.STL" />
      </geometry>
    </collision>
  </link>

  <joint  name="joint_9"  type="revolute">
    <origin  xyz="0.024099 -0.004 0.025382"  rpy="0 0 0" />
    <parent  link="link_5" />
    <child  link="link_9" />
    <axis  xyz="0 -1 0" />
    <limit  lower="-0.8"  upper="0.8"  effort="100"  velocity="3" />
  </joint>

  <link  name="link_6">
    <inertial>
      <origin  xyz="-0.0129506495019555 0.00700000000000344 0.011812320726033"  rpy="0 0 0" />
      <mass  value="0.00108778506953505" />
      <inertia
        ixx="8.86285716063773E-08"
        ixy="1.85493072054669E-21"
        ixz="8.30022521497664E-08"
        iyy="1.71922619588063E-07"
        iyz="-1.87701277774844E-21"
        izz="8.49257255859881E-08" />
    </inertial>
    <visual>
      <origin  xyz="0 0 0"  rpy="0 0 0" />
      <geometry>
        <mesh  filename="package://streeing_arm/meshes/link_6.STL" />
      </geometry>
      <material  name="">
        <color  rgba="0.741176470588235 0.901960784313726 0.956862745098039 1" />
      </material>
    </visual>
    <collision>
      <origin  xyz="0 0 0"  rpy="0 0 0" />
      <geometry>
        <mesh  filename="package://streeing_arm/meshes/link_6.STL" />
      </geometry>
    </collision>
  </link>

  <joint  name="joint_6"  type="revolute">
    <origin  xyz="0.054203 0.012934 0.045287"  rpy="0.13973 0 -3.1416" />
    <parent  link="link_3" />
    <child  link="link_6" />
    <axis  xyz="0 -1 0" />
    <limit  lower="-0.8"  upper="0.8"  effort="100"  velocity="3" />
  </joint>

  <link  name="link_7">
    <inertial>
      <origin    xyz="0.0127747670306929 0.00699999999999876 0.0120023151330441"   rpy="0 0 0" />
      <mass  value="0.00108778506953505" />
      <inertia
        ixx="9.10794072428584E-08"
        ixy="-3.95365195528865E-22"
        ixz="-8.29113514522176E-08"
        iyy="1.71922619588062E-07"
        iyz="-4.47487143181348E-22"
        izz="8.24748899495065E-08" />
    </inertial>
    <visual>
      <origin  xyz="0 0 0"  rpy="0 0 0" />
      <geometry>
        <mesh  filename="package://streeing_arm/meshes/link_7.STL" />
      </geometry>
      <material  name="">
        <color  rgba="0.741176470588235 0.901960784313726 0.956862745098039 1" />
      </material>
    </visual>
    <collision>
      <origin  xyz="0 0 0"  rpy="0 0 0" />
      <geometry>
        <mesh  filename="package://streeing_arm/meshes/link_7.STL" />
      </geometry>
    </collision>
  </link>

  <joint  name="joint_7"  type="revolute">
    <origin  xyz="-0.011203 0.012934 0.045287"  rpy="0.13973 0 -3.1416" />
    <parent  link="link_3" />
    <child  link="link_7" />
    <axis  xyz="0 -1 0" />
    <limit  lower="-0.8"  upper="0.8"  effort="100"  velocity="3" />
  </joint>

</robot>
